Traceback (most recent call last):
  File "/Users/mikemorris/opt/anaconda3/envs/UTCDW/lib/python3.9/site-packages/jupyter_cache/executors/utils.py", line 58, in single_nb_execution
    executenb(
  File "/Users/mikemorris/opt/anaconda3/envs/UTCDW/lib/python3.9/site-packages/nbclient/client.py", line 1305, in execute
    return NotebookClient(nb=nb, resources=resources, km=km, **kwargs).execute()
  File "/Users/mikemorris/opt/anaconda3/envs/UTCDW/lib/python3.9/site-packages/jupyter_core/utils/__init__.py", line 168, in wrapped
    return loop.run_until_complete(inner)
  File "/Users/mikemorris/opt/anaconda3/envs/UTCDW/lib/python3.9/asyncio/base_events.py", line 647, in run_until_complete
    return future.result()
  File "/Users/mikemorris/opt/anaconda3/envs/UTCDW/lib/python3.9/site-packages/nbclient/client.py", line 705, in async_execute
    await self.async_execute_cell(
  File "/Users/mikemorris/opt/anaconda3/envs/UTCDW/lib/python3.9/site-packages/nbclient/client.py", line 1058, in async_execute_cell
    await self._check_raise_for_error(cell, cell_index, exec_reply)
  File "/Users/mikemorris/opt/anaconda3/envs/UTCDW/lib/python3.9/site-packages/nbclient/client.py", line 914, in _check_raise_for_error
    raise CellExecutionError.from_cell_and_msg(cell, exec_reply_content)
nbclient.exceptions.CellExecutionError: An error occurred while executing the following cell:
------------------
# download data for this station for an earlier period
df_1950_1991 = download_station_data(stn_ids_toronto_city[0], years = range(1950, 1992))

# stitch together with what we had already
df_toronto_city_longrecord = df_1950_1991.append(df_toronto_city)                                 
------------------


[0;31m---------------------------------------------------------------------------[0m
[0;31mAttributeError[0m                            Traceback (most recent call last)
[0;32m/var/folders/nt/0d8x2n0x1bdbrmp50m9nn6f00000gn/T/ipykernel_13374/1386844892.py[0m in [0;36m?[0;34m()[0m
[0;32m----> 5[0;31m [0;31m# download data for this station for an earlier period[0m[0;34m[0m[0;34m[0m[0m
[0m[1;32m      6[0m [0mdf_1950_1991[0m [0;34m=[0m [0mdownload_station_data[0m[0;34m([0m[0mstn_ids_toronto_city[0m[0;34m[[0m[0;36m0[0m[0;34m][0m[0;34m,[0m [0myears[0m [0;34m=[0m [0mrange[0m[0;34m([0m[0;36m1950[0m[0;34m,[0m [0;36m1992[0m[0;34m)[0m[0;34m)[0m[0;34m[0m[0;34m[0m[0m
[1;32m      7[0m [0;34m[0m[0m
[1;32m      8[0m [0;31m# stitch together with what we had already[0m[0;34m[0m[0;34m[0m[0m

[0;32m~/opt/anaconda3/envs/UTCDW/lib/python3.9/site-packages/pandas/core/generic.py[0m in [0;36m?[0;34m(self, name)[0m
[1;32m   6200[0m             [0;32mand[0m [0mname[0m [0;32mnot[0m [0;32min[0m [0mself[0m[0;34m.[0m[0m_accessors[0m[0;34m[0m[0;34m[0m[0m
[1;32m   6201[0m             [0;32mand[0m [0mself[0m[0;34m.[0m[0m_info_axis[0m[0;34m.[0m[0m_can_hold_identifiers_and_holds_name[0m[0;34m([0m[0mname[0m[0;34m)[0m[0;34m[0m[0;34m[0m[0m
[1;32m   6202[0m         ):
[1;32m   6203[0m             [0;32mreturn[0m [0mself[0m[0;34m[[0m[0mname[0m[0;34m][0m[0;34m[0m[0;34m[0m[0m
[0;32m-> 6204[0;31m         [0;32mreturn[0m [0mobject[0m[0;34m.[0m[0m__getattribute__[0m[0;34m([0m[0mself[0m[0;34m,[0m [0mname[0m[0;34m)[0m[0;34m[0m[0;34m[0m[0m
[0m
[0;31mAttributeError[0m: 'DataFrame' object has no attribute 'append'

